<?xml version="1.0"?>
<robot xmlns:xacro="http://wiki.ros.org/xacro">

  <xacro:macro name="kuka_kr16_2" params="prefix">
  
    <!-- Define constants -->
    <xacro:property name="deg" value="0.017453293"/>
    <xacro:property name="link_mass_0" value="150"/>
    <xacro:property name="link_mass_1" value="138"/>
    <xacro:property name="link_mass_2" value="95"/>
    <xacro:property name="link_mass_3" value="71"/>
    <xacro:property name="link_mass_4" value="17"/>
    <xacro:property name="link_mass_5" value="7"/>
    <xacro:property name="link_mass_6" value="0.5"/>


    <!-- Import gazebo elements -->
    <xacro:include filename="$(find kuka_kr16_support)/urdf/kr16.gazebo.xacro"/>
    
    <!-- LINKS -->
    <link name="world"/>
    <!-- base link -->
    <link name="${prefix}base_link">
      <inertial>
        <origin xyz="0 0 0" rpy="0 0 0"/>
        <mass value="${link_mass_0}"/>
        <inertia ixx="60" ixy="0" ixz="0" iyy="70" iyz="0" izz="100" />
      </inertial>
      <visual>
        <origin xyz="0 0 0" rpy="0 0 0"/>
        <geometry>
          <mesh filename="package://kuka_kr16_support/meshes/kr16_2/visual/base_link.dae" />
        </geometry>
      </visual>
      <collision>
        <origin xyz="0 0 0" rpy="0 0 0"/>
        <geometry>
          <mesh filename="package://kuka_kr16_support/meshes/kr16_2/collision/base_link.stl" />
        </geometry>
      </collision>
    </link>
    <!-- link 1 (A1) -->
    <link name="${prefix}link_1">
      <inertial>
        <origin xyz="0 0 0" rpy="0 0 0"/>
        <mass value="${link_mass_1}"/>
        <inertia ixx="30" ixy="0" ixz="0" iyy="50" iyz="0" izz="50" />
      </inertial>
      <visual>
        <origin xyz="0 0 0" rpy="0 0 0"/>
        <geometry>
          <mesh filename="package://kuka_kr16_support/meshes/kr16_2/visual/link_1.dae" />
        </geometry>
      </visual>
      <collision>
        <origin xyz="0 0 0" rpy="0 0 0"/>
        <geometry>
          <mesh filename="package://kuka_kr16_support/meshes/kr16_2/collision/link_1.stl" />
        </geometry>
      </collision>
    </link>
    <!-- link 2 -->
    <link name="${prefix}link_2">
      <inertial>
        <origin xyz="0 0 0" rpy="0 0 0"/>
        <mass value="${link_mass_2}"/>
        <inertia ixx="40" ixy="0" ixz="0" iyy="40" iyz="0" izz="10" />
      </inertial>
      <visual>
        <origin xyz="0 0 0" rpy="0 0 0"/>
        <geometry>
          <mesh filename="package://kuka_kr16_support/meshes/kr16_2/visual/link_2.dae"/>
        </geometry>
      </visual>
      <collision>
        <origin xyz="0 0 0" rpy="0 0 0"/>
        <geometry>
          <mesh filename="package://kuka_kr16_support/meshes/kr16_2/collision/link_2.stl" />
        </geometry>
      </collision>
    </link>
    <!-- link 3 -->
    <link name="${prefix}link_3">
      <inertial>
        <origin xyz="0 0 0" rpy="0 0 0"/>
        <mass value="${link_mass_3}"/>
        <inertia ixx="1" ixy="0" ixz="0" iyy="10" iyz="0" izz="10" />
      </inertial>
      <visual>
        <origin xyz="0 0 0" rpy="0 0 0"/>
        <geometry>
          <mesh filename="package://kuka_kr16_support/meshes/kr16_2/visual/link_3.dae" />
        </geometry>
      </visual>
      <collision>
        <origin xyz="0 0 0" rpy="0 0 0"/>
        <geometry>
          <mesh filename="package://kuka_kr16_support/meshes/kr16_2/collision/link_3.stl" />
        </geometry>
      </collision>
    </link>
    <!-- link 4 -->
    <link name="${prefix}link_4">
      <inertial>
        <origin xyz="0 0 0" rpy="0 0 0"/>
        <mass value="${link_mass_4}"/>
        <inertia ixx="0.18" ixy="0" ixz="0" iyy="0.55" iyz="0" izz="0.64" />
      </inertial>
      <visual>
        <origin xyz="0 0 0" rpy="0 0 0"/>
        <geometry>
          <mesh filename="package://kuka_kr16_support/meshes/kr16_2/visual/link_4.dae" />
        </geometry>
      </visual>
      <collision>
        <origin xyz="0 0 0" rpy="0 0 0"/>
        <geometry>
          <mesh filename="package://kuka_kr16_support/meshes/kr16_2/collision/link_4.stl" />
        </geometry>
      </collision>
    </link>
    <!-- link 5 -->
    <link name="${prefix}link_5">
      <inertial>
        <origin xyz="0 0 0" rpy="0 0 0"/>
        <mass value="${link_mass_5}"/>
        <inertia ixx="0.04" ixy="0" ixz="0" iyy="0.068" iyz="0" izz="0.068" />
      </inertial>
      <visual>
        <origin xyz="0 0 0" rpy="0 0 0"/>
        <geometry>
          <mesh filename="package://kuka_kr16_support/meshes/kr16_2/visual/link_5.dae" />
        </geometry>
      </visual>
      <collision>
        <origin xyz="0 0 0" rpy="0 0 0"/>
        <geometry>
          <mesh filename="package://kuka_kr16_support/meshes/kr16_2/collision/link_5.stl" />
        </geometry>
      </collision>
    </link>
    <!-- link 6 -->
    <link name="${prefix}link_6">
      <inertial>
        <origin xyz="0 0 0" rpy="0 0 0"/>
        <mass value="${link_mass_6}"/>
        <inertia ixx="0.004" ixy="0" ixz="0" iyy="0.003" iyz="0" izz="0.003" />
      </inertial>
      <visual>
        <origin xyz="0 0 0" rpy="0 0 0"/>
        <geometry>
          <mesh filename="package://kuka_kr16_support/meshes/kr16_2/visual/link_6.dae" />
        </geometry>
      </visual>
      <collision>
        <origin xyz="0 0 0" rpy="0 0 0"/>
        <geometry>
          <mesh filename="package://kuka_kr16_support/meshes/kr16_2/collision/link_6.stl" />
        </geometry>
      </collision>
    </link>
       
    <!-- END LINKS -->
    <!-- gripper -->
      
    <!-- Define constants -->
    <xacro:property name="gripper_mass" value="0.3"/>
    <xacro:property name="finger_mass" value="0.1"/>
    <xacro:property name="gripper_type" value="two_finger"/>
    <xacro:property name="vacuum_gripper_radius" value="0.1"/>
    <xacro:if value="${gripper_type == 'vacuum'}">
    <link name="${prefix}gripper_link">
      <inertial>
        <origin xyz="0 0 0" rpy="0 0 0"/>
        <mass value="${gripper_mass}"/>
        <inertia ixx="0.005" ixy="0" ixz="0" iyy="0.00" iyz="0" izz="0.00"/>
      </inertial>
      <visual>
        <origin xyz="0 0 0" rpy="0 0 0"/>
        <geometry>
          <sphere radius="${vacuum_gripper_radius}"/>
        </geometry>
      </visual>
      <collision>
        <origin xyz="0 0 0" rpy="0 0 0"/>
        <geometry>
          <sphere radius="${vacuum_gripper_radius}"/>
        </geometry>
      </collision>
    </link>
    <joint name="${prefix}gripper_joint" type="fixed">
      <parent link="${prefix}link_6"/>
      <child link="${prefix}gripper_link"/>
      <origin xyz="0.0375 0 0" rpy="0 0 0"/>
    </joint>
    </xacro:if>

    <!--Two-finger gripper-->
    <xacro:if value="${gripper_type == 'two_finger'}">
    <link name="${prefix}gripper_link">
      <inertial>
        <origin xyz="0 0 0" rpy="0 0 0"/>
        <mass value="${gripper_mass}"/>
        <inertia ixx="0.0001" ixy="0" ixz="0" iyy="0.0002" iyz="0" izz="0.0001"/>
      </inertial>
      <visual>
        <origin xyz="0 0 0" rpy="0 0 0"/>
        <geometry>
          <mesh filename="package://kuka_kr16_support/meshes/kr16_2/gripper/gripper_base.dae"/>
        </geometry>
      </visual>
      <collision>
        <origin xyz="0 0 0" rpy="0 0 0"/>
        <geometry>
          <mesh filename="package://kuka_kr16_support/meshes/kr16_2/gripper/gripper_base.dae"/>
        </geometry>
      </collision>
    </link>
    <link name="${prefix}right_gripper_finger_link">
      <inertial>
        <origin xyz="0 0 0" rpy="0 0 0"/>
        <mass value="${finger_mass}"/>
        <inertia ixx="0.002" ixy="0" ixz="0" iyy="0.0002" iyz="0" izz="0.0002"/>
      </inertial>
      <visual>
        <origin xyz="0 0 0" rpy="0 0 0"/>
        <geometry>
          <mesh filename="package://kuka_kr16_support/meshes/kr16_2/gripper/finger_right.dae"/>
        </geometry>
      </visual>
      <collision>
        <origin xyz="0 0 0" rpy="0 0 0"/>
        <geometry>
          <mesh filename="package://kuka_kr16_support/meshes/kr16_2/gripper/finger_right_collision.dae"/>
        </geometry>
      </collision>
    </link>
    <link name="${prefix}left_gripper_finger_link">
      <inertial>
        <origin xyz="0 0 0" rpy="0 0 0"/>
        <mass value="${finger_mass}"/>
        <inertia ixx="0.002" ixy="0" ixz="0" iyy="0.0002" iyz="0" izz="0.0002"/>
      </inertial>
      <visual>
        <origin xyz="0 0 0" rpy="0 0 0"/>
        <geometry>
          <mesh filename="package://kuka_kr16_support/meshes/kr16_2/gripper/finger_left.dae"/>
        </geometry>
      </visual>
      <collision>
        <origin xyz="0 0 0" rpy="0 0 0"/>
        <geometry>
          <mesh filename="package://kuka_kr16_support/meshes/kr16_2/gripper/finger_left_collision.dae"/>
        </geometry>
      </collision>
    </link>
    
    <joint name="${prefix}right_gripper_finger_joint" type="prismatic">
      <origin rpy="0 0 0" xyz="0.15 -0.0725 0" />
      <parent link="${prefix}gripper_link" />
      <child link="${prefix}right_gripper_finger_link" />
      <axis xyz="0 1 0" />
      <limit effort="100" lower="-0.01" upper="0.06" velocity="0.05" />
      <dynamics damping="0.7" />
    </joint>
    <joint name="${prefix}left_gripper_finger_joint" type="prismatic">
      <origin rpy="0 0 0" xyz="0.15 0.0725 0" />
      <parent link="${prefix}gripper_link" />
      <child link="${prefix}left_gripper_finger_link" />
      <axis xyz="0 -1 0" />
      <limit effort="100" lower="-0.01" upper="0.06" velocity="0.05" />
      <dynamics damping="0.7" />
    </joint>
    <joint name="${prefix}gripper_joint" type="fixed">
      <parent link="${prefix}link_6"/>
      <child link="${prefix}gripper_link"/>
      <origin xyz="0.11 0 0" rpy="0 0 0"/><!--0.087-->
      <axis xyz="0 1 0" />
    </joint>

    <transmission name="tran7">
      <type>transmission_interface/SimpleTransmission</type>
      <joint name="left_gripper_finger_joint">
        <hardwareInterface>hardware_interface/EffortJointInterface</hardwareInterface>
      </joint>
      <actuator name="motor7">
        <hardwareInterface>hardware_interface/EffortJointInterface</hardwareInterface>
        <mechanicalReduction>1</mechanicalReduction>
      </actuator>
    </transmission>

    <transmission name="tran8">
      <type>transmission_interface/SimpleTransmission</type>
      <joint name="right_gripper_finger_joint">
        <hardwareInterface>hardware_interface/EffortJointInterface</hardwareInterface>
      </joint>
      <actuator name="motor8">
        <hardwareInterface>hardware_interface/EffortJointInterface</hardwareInterface>
        <mechanicalReduction>1</mechanicalReduction>
      </actuator>
    </transmission>
    </xacro:if> 
    
    <!-- JOINTS -->
    <joint name="${prefix}fixed_base_joint" type="fixed">
      <parent link="${prefix}world"/>
      <child link="${prefix}base_link"/>
      <origin xyz="0 0 0" rpy="0 0 0"/>
    </joint>
    <!-- joint 1 (A1) -->
    <joint name="${prefix}joint_a1" type="revolute">
      <origin xyz="0 0 0.675" rpy="0 0 0"/>
      <parent link="${prefix}base_link"/>
      <child link="${prefix}link_1"/>
      <axis xyz="0 0 1"/>
      <limit effort="0" lower="${radians(-185)}" upper="${radians(185)}" velocity="${radians(156)}"/>
    </joint>
    <!-- joint 2 (A2) -->
    <joint name="${prefix}joint_a2" type="revolute">
      <origin xyz="0.26 0 0" rpy="0 0 0"/>
      <parent link="${prefix}link_1"/>
      <child link="${prefix}link_2"/>
      <axis xyz="0 1 0"/>
      <limit effort="0" lower="${radians(-155)}" upper="${radians(35)}" velocity="${radians(156)}"/>
    </joint>
    <!-- joint 3 (A3) -->
    <joint name="${prefix}joint_a3" type="revolute">
      <origin xyz="0.68 0 0" rpy="0 0 0"/>
      <parent link="${prefix}link_2"/>
      <child link="${prefix}link_3"/>
      <axis xyz="0 1 0"/>
      <limit effort="0" lower="${radians(-130)}" upper="${radians(154)}" velocity="${radians(156)}"/>
    </joint>
    <!-- joint 4 (A4) -->
    <joint name="${prefix}joint_a4" type="revolute">
      <origin xyz="0.67 0 -0.035" rpy="0 0 0"/>
      <parent link="${prefix}link_3"/>
      <child link="${prefix}link_4"/>
      <axis xyz="1 0 0"/>
      <limit effort="0" lower="${radians(-350)}" upper="${radians(350)}" velocity="${radians(330)}"/>
    </joint>
    <!-- joint 5 (A5) -->
    <joint name="${prefix}joint_a5" type="revolute">
      <origin xyz="0 0 0" rpy="0 0 0"/>
      <parent link="${prefix}link_4"/>
      <child link="${prefix}link_5"/>
      <axis xyz="0 1 0"/>
      <limit effort="0" lower="${radians(-130)}" upper="${radians(130)}" velocity="${radians(330)}"/>
    </joint>
    <!-- joint 6 (A6) -->
    <joint name="${prefix}joint_a6" type="revolute">
      <origin xyz="0 0 0" rpy="0 0 0"/>
      <parent link="${prefix}link_5"/>
      <child link="${prefix}link_6"/>
      <axis xyz="1 0 0"/>
      <limit effort="0" lower="${radians(-350)}" upper="${radians(350)}" velocity="${radians(615)}"/>
    </joint>
    <!-- END JOINTS -->
    <xacro:include filename="$(find kuka_kr16_support)/urdf/transmission.xacro" />
  </xacro:macro>
</robot>
